'use client';

import React, { Component, ErrorInfo, ReactNode } from 'react';
import { Button } from './button';
import { Card, CardContent, CardHeader, CardTitle } from './card';

interface Props {
  children: ReactNode;
  fallback?: ReactNode;
}

interface State {
  hasError: boolean;
  error?: Error;
}

export class ErrorBoundary extends Component<Props, State> {
  constructor(props: Props) {
    super(props);
    this.state = { hasError: false };
  }

  static getDerivedStateFromError(error: Error): State {
    return { hasError: true, error };
  }

  componentDidCatch(error: Error, errorInfo: ErrorInfo) {
    console.error('Error caught by boundary:', error, errorInfo);
  }

  handleRetry = () => {
    this.setState({ hasError: false, error: undefined });
  };

  render() {
    if (this.state.hasError) {
      if (this.props.fallback) {
        return this.props.fallback;
      }

      return (
        <div className="min-h-screen flex items-center justify-center bg-white p-4">
          <Card className="w-full max-w-md">
            <CardHeader>
              <CardTitle className="text-red-600">Something went wrong</CardTitle>
            </CardHeader>
            <CardContent className="space-y-4">
              <p className="text-gray-600">
                We encountered an unexpected error. Please try again.
              </p>
              {process.env.NODE_ENV === 'development' && this.state.error && (
                <details className="text-sm text-gray-500">
                  <summary className="cursor-pointer">Error details</summary>
                  <pre className="mt-2 whitespace-pre-wrap">
                    {this.state.error.message}
                  </pre>
                </details>
              )}
              <Button onClick={this.handleRetry} className="w-full">
                Try Again
              </Button>
            </CardContent>
          </Card>
        </div>
      );
    }

    return this.props.children;
  }
}
